Workbook
Name Parent_Name: [1]SPWR!$E$7
Name Sub_Discount_Rate: #REF!
Name Sub_Name: [1]MAXN!$E$7
Name Sub_New_Share_Price: [1]MAXN_Adj!$E$12
Name Sub_Tax_Rate: [1]MAXN_Adj!$E$23
Name Sub_Terminal_Growth_Rate: #REF!
Name Sub_Terminal_Multiple: #REF!
Name Sub_Total_Shares: [1]MAXN_Adj!$E$21
Name tgr: 'WBD SOTP'!$L$11
Name wacc: 'WBD SOTP'!$L$10

Sheet NFLX Income Statement - GAAP
A2: Netflix Inc (NFLX US) - BBG GAAP
A4: In Millions of USD except Per Share | C4: FY 2018 | D4: FY 2019 | E4: FY 2020 | F4: FY 2021 | G4: FY 2022 | H4: FY 2023 | I4: FY 2024 | J4: Last 12M | K4: FY 2025 Est | L4: FY 2026 Est
A5: 12 Months Ending | C5: 12/31/2018 | D5: 12/31/2019 | E5: 12/31/2020 | F5: 12/31/2021 | G5: 12/31/2022 | H5: 12/31/2023 | I5: 12/31/2024 | J5: 09/30/2025 | K5: 12/31/2025 | L5: 12/31/2026
A6: Revenue | B6: SALES_REV_TURN | C6: 15794.341 | D6: 20156.447 | E6: 24996.056 | F6: 29697.844 | G6: 31615.55 | H6: 33723.297 | I6: 39000.966 | J6: 43378.787 | K6: 45102.022 | L6: 50935.319
D7: =(D6/C6)-1 -> 0.27618158 | E7: =(E6/D6)-1 -> 0.24010229 | F7: =(F6/E6)-1 -> 0.18810119 | G7: =(G6/F6)-1 -> 0.064573913 | H7: =(H6/G6)-1 -> 0.066668048 | I7: =(I6/H6)-1 -> 0.1564992 | M7: =AVERAGE(D7:I7) -> 0.16535437
A8: + Sales & Services Revenue | B8: IS_SALES_AND_SERVICES_REVENUES | C8: 15794.341 | D8: 20156.447 | E8: 24996.056 | F8: 29697.844 | G8: 31615.55 | H8: 33723.297 | I8: 39000.966 | J8: 43378.787
A9: - Cost of Revenue | B9: IS_COGS_TO_FE_AND_PP_AND_G | C9: 9967.538 | D9: 12440.213 | E9: 15276.319 | F9: 17332.683 | G9: 19168.285 | H9: 19715.368 | I9: 21038.464 | J9: 22520.072
A10: + Cost of Goods & Services | B10: IS_COG_AND_SERVICES_SOLD | C10: 9967.538 | D10: 12440.213 | E10: 15276.319 | F10: 17332.683 | G10: 19168.285 | H10: 19715.368 | I10: 21038.464 | J10: 22520.072
A11: Gross Profit | B11: GROSS_PROFIT | C11: 5826.803 | D11: 7716.234 | E11: 9719.737 | F11: 12365.161 | G11: 12447.265 | H11: 14007.929 | I11: 17962.502 | J11: 20858.715 | K11: 21797.807 | L11: 25820.132
A12: + Other Operating Income | B12: IS_OTHER_OPER_INC | C12: 0 | D12: 0 | E12: 0 | F12: 0 | G12: 0 | H12: 0 | I12: 0 | J12: 0
A13: - Operating Expenses | B13: IS_OPERATING_EXPN | C13: 4221.577 | D13: 5111.98 | E13: 5134.448 | F13: 6170.652 | G13: 6814.434 | H13: 7053.926 | I13: 7544.888 | J13: 8216.009
A14: + Selling, General & Admin | B14: IS_SGA_EXPENSE | C14: 2999.763 | D14: 3566.831 | E14: 3304.848 | F14: 3896.767 | G14: 4103.393 | H14: 4378.168 | I14: 4619.593 | J14: 4938.414
A15: + Selling & Marketing | B15: IS_SELLING_EXPENSES | C15: 2369.469 | D15: 2652.462 | E15: 2228.362 | F15: 2545.146 | G15: 2530.502 | H15: 2657.883 | I15: 2917.554 | J15: 3164.134
A16: + General & Administrative | B16: IS_GENERAL_AND_ADMINISTRATIVE | C16: 630.294 | D16: 914.369 | E16: 1076.486 | F16: 1351.621 | G16: 1572.891 | H16: 1720.285 | I16: 1702.039 | J16: 1774.28
A17: + Research & Development | B17: IS_OPER_EXPENSES_RD_GAAP | C17: 1221.814 | D17: 1545.149 | E17: 1829.6 | F17: 2273.885 | G17: 2711.041 | H17: 2675.758 | I17: 2925.295 | J17: 3277.595
A18: + Other Operating Expense | B18: OTHER_OPERATING_EXPENSES_RATIO | C18: 0 | D18: 0 | E18: 0 | F18: 0 | G18: 0 | H18: 0 | I18: 0 | J18: 0
A19: Operating Income (Loss) | B19: IS_OPER_INC | C19: 1605.226 | D19: 2604.254 | E19: 4585.289 | F19: 6194.509 | G19: 5632.831 | H19: 6954.003 | I19: 10417.614 | J19: 12642.706 | K19: 13253.878 | L19: 16565.933
A20: - Non-Operating (Income) Loss | B20: NONOP_INCOME_LOSS | C20: 378.768 | D20: 542.023 | E20: 1385.94 | F20: 354.406 | G20: 368.902 | H20: 748.598 | I20: 451.957 | J20: 553.627
A21: + Interest Expense, Net | B21: IS_NET_INTEREST_EXPENSE | C21: 420.493 | D21: 626.023 | E21: 767.499 | F21: 765.62 | G21: 706.212 | H21: 699.826 | I21: 718.733 | J21: 734.718
A22: + Interest Expense | B22: IS_INT_EXPENSE | C22: 420.493 | D22: 626.023 | E22: 767.499 | F22: 765.62 | G22: 706.212 | H22: 699.826 | I22: 718.733 | J22: 734.718
A23: - Interest Income | B23: IS_INT_INC | C23: 0 | D23: 0 | E23: 0 | F23: 0 | G23: 0 | H23: 0 | I23: 0 | J23: 0
A24: + Foreign Exch (Gain) Loss | B24: IS_FOREIGN_EXCH_LOSS | C24: 0 | D24: 0 | E24: 0 | F24: 0 | G24: 0 | H24: 0 | I24: 0
A25: + (Income) Loss from Affiliates | B25: INCOME_LOSS_FROM_AFFILIATES | C25: — | D25: — | E25: — | F25: — | G25: — | H25: — | I25: —
A26: + Other Non-Op (Income) Loss | B26: OTHER_NONOP_INCOME_LOSS | C26: -41.725 | D26: -84 | E26: 618.441 | F26: -411.214 | G26: -337.31 | H26: 48.772 | I26: -266.776 | J26: -181.091
A27: Pretax Income | B27: PRETAX_INC | C27: 1226.458 | D27: 2062.231 | E27: 3199.349 | F27: 5840.103 | G27: 5263.929 | H27: 6205.405 | I27: 9965.657 | J27: 12089.079 | K27: 12737.103 | L27: 16118.9
A28: - Income Tax Expense (Benefit) | B28: IS_INC_TAX_EXP | C28: 15.216 | D28: 195.315 | E28: 437.954 | F28: 723.875 | G28: 772.005 | H28: 797.415 | I28: 1254.026 | J28: 1657.792
A29: + Current Income Tax | B29: IS_CURRENT_INCOME_TAX_BENEFIT | C29: 100.736 | D29: 290.054 | E29: 367.888 | F29: 524.356 | G29: 906.532 | H29: 1340.393 | I29: 1845.396
A30: + Deferred Income Tax | B30: IS_DEFERRED_INCOME_TAX_BENEFIT | C30: -85.52 | D30: -94.739 | E30: 70.066 | F30: 199.519 | G30: -134.527 | H30: -542.978 | I30: -591.37
A31: + Tax Allowance/Credit | B31: IS_TAX_VALN_ALLOWNCE_CREDITS | C31: — | D31: — | E31: — | F31: — | G31: — | H31: — | I31: —
A32: Income (Loss) from Cont Ops | B32: IS_INC_BEF_XO_ITEM | C32: 1211.242 | D32: 1866.916 | E32: 2761.395 | F32: 5116.228 | G32: 4491.924 | H32: 5407.99 | I32: 8711.631 | J32: 10431.287 | K32: 10960.628 | L32: 13838.689
A33: - Net Extraordinary Losses (Gains) | B33: XO_GL_NET_OF_TAX | C33: 0 | D33: 0 | E33: 0 | F33: 0 | G33: 0 | H33: 0 | I33: 0 | J33: 0
A34: + Discontinued Operations | B34: IS_DISCONTINUED_OPERATIONS | C34: 0 | D34: 0 | E34: 0 | F34: 0 | G34: 0 | H34: 0 | I34: 0 | J34: 0
A35: + XO & Accounting Changes | B35: EXTRAORD_ITEMS_ACCOUNTING_CHANGS | C35: 0 | D35: 0 | E35: 0 | F35: 0 | G35: 0 | H35: 0 | I35: 0 | J35: 0
A36: Income (Loss) Incl. MI | B36: NI_INCLUDING_MINORITY_INT_RATIO | C36: 1211.242 | D36: 1866.916 | E36: 2761.395 | F36: 5116.228 | G36: 4491.924 | H36: 5407.99 | I36: 8711.631 | J36: 10431.287
A37: - Minority Interest | B37: MIN_NONCONTROL_INTEREST_CREDITS | C37: 0 | D37: 0 | E37: 0 | F37: 0 | G37: 0 | H37: 0 | I37: 0 | J37: 0
A38: Net Income, GAAP | B38: NET_INCOME | C38: 1211.242 | D38: 1866.916 | E38: 2761.395 | F38: 5116.228 | G38: 4491.924 | H38: 5407.99 | I38: 8711.631 | J38: 10431.287 | K38: 10960.628 | L38: 13838.689
A39: - Preferred Dividends | B39: IS_TOT_CASH_PFD_DVD | C39: 0 | D39: 0 | E39: 0 | F39: 0 | G39: 0 | H39: 0 | I39: 0 | J39: 0
A40: - Other Adjustments | B40: OTHER_ADJUSTMENTS | C40: 0 | D40: 0 | E40: 0 | F40: 0 | G40: 0 | H40: 0 | I40: 0 | J40: 0
A41: Net Income Avail to Common, GAAP | B41: EARN_FOR_COMMON | C41: 1211.242 | D41: 1866.916 | E41: 2761.395 | F41: 5116.228 | G41: 4491.924 | H41: 5407.99 | I41: 8711.631 | J41: 10431.287 | K41: 10960.628 | L41: 13838.689
A43: Net Income Avail to Common, Adj | B43: EARN_FOR_COMMON | C43: 1211.242 | D43: 1866.916 | E43: 3607.395 | F43: 4894.228 | G43: 4331.4663 | H43: 5547.2638 | I43: 8615.6152 | J43: 10454.373 | K43: 11118.692 | L43: 13890.083
...

Sheet NFLX Balance Sheet 
A2: Netflix Inc (NFLX US) - Standardized
A4: In Millions of USD except Per Share | C4: FY 2015 | D4: FY 2016 | E4: FY 2017 | F4: FY 2018 | G4: FY 2019 | H4: FY 2020 | I4: FY 2021 | J4: FY 2022 | K4: FY 2023 | L4: FY 2024
A5: 12 Months Ending | C5: 12/31/2015 | D5: 12/31/2016 | E5: 12/31/2017 | F5: 12/31/2018 | G5: 12/31/2019 | H5: 12/31/2020 | I5: 12/31/2021 | J5: 12/31/2022 | K5: 12/31/2023 | L5: 12/31/2024
A6: Total Assets
A7: + Cash, Cash Equivalents & STI | B7: CASH_CASH_EQTY_STI_DETAILED | C7: 2310.715 | D7: 1733.782 | E7: 2822.795 | F7: 3794.483 | G7: 5018.437 | H7: 8205.55 | I7: 6027.804 | J7: 6058.452 | K7: 7137.886 | L7: 9583.739
A8: + Cash & Cash Equivalents | B8: BS_CASH_NEAR_CASH_ITEM | C8: 1809.33 | D8: 1467.576 | E8: 2822.795 | F8: 3794.483 | G8: 5018.437 | H8: 8205.55 | I8: 6027.804 | J8: 5147.176 | K8: 7116.913 | L8: 7804.733
A9: + ST Investments | B9: BS_MKT_SEC_OTHER_ST_INVEST | C9: 501.385 | D9: 266.206 | E9: 0 | F9: 0 | G9: 0 | H9: 0 | I9: 0 | J9: 911.276 | K9: 20.973 | L9: 1779.006
A10: + Accounts & Notes Receiv | B10: BS_ACCT_NOTE_RCV | C10: 0 | D10: 0 | E10: 0 | F10: 362.712 | G10: 454.399 | H10: 610.819 | I10: 804.32 | J10: 988.898 | K10: 1287.054 | L10: 1335.304
A11: + Accounts Receivable, Net | B11: BS_ACCTS_REC_EXCL_NOTES_REC | C11: 0 | D11: 0 | E11: 0 | F11: 362.712 | G11: 454.399 | H11: 610.819 | I11: 804.32 | J11: 988.898 | K11: 1287.054 | L11: 1335.304
A12: + Notes Receivable, Net | B12: NOTES_RECEIVABLE | C12: 0 | D12: 0 | E12: 0 | F12: 0 | G12: 0 | H12: 0 | I12: 0 | J12: 0 | K12: 0 | L12: 0
A13: + Inventories | B13: BS_INVENTORIES | C13: 0 | D13: 0 | E13: 0 | F13: 0 | G13: 0 | H13: 0 | I13: 0 | J13: 0 | K13: 0 | L13: 0
A14: + Raw Materials | B14: INVTRY_RAW_MATERIALS | C14: 0 | D14: 0 | E14: 0 | F14: 0 | G14: 0 | H14: 0 | I14: 0 | J14: 0 | K14: 0 | L14: 0
A15: + Work In Process | B15: INVTRY_IN_PROGRESS | C15: 0 | D15: 0 | E15: 0 | F15: 0 | G15: 0 | H15: 0 | I15: 0 | J15: 0 | K15: 0 | L15: 0
A16: + Finished Goods | B16: INVTRY_FINISHED_GOODS | C16: 0 | D16: 0 | E16: 0 | F16: 0 | G16: 0 | H16: 0 | I16: 0 | J16: 0 | K16: 0 | L16: 0
A17: + Other Inventory | B17: BS_OTHER_INV | C17: 0 | D17: 0 | E17: 0 | F17: 0 | G17: 0 | H17: 0 | I17: 0 | J17: 0 | K17: 0 | L17: 0
A18: + Other ST Assets | B18: OTHER_CURRENT_ASSETS_DETAILED | C18: 3121.125 | D18: 3986.509 | E18: 4847.179 | F18: 5536.94 | G18: 705.668 | H18: 945.211 | I18: 1237.701 | J18: 2219.123 | K18: 1493.193 | L18: 2181.336
A19: + Prepaid Expenses | B19: BS_PREPAY | C19: — | D19: — | E19: — | F19: 178.833 | G19: 180.999 | H19: 203.042 | I19: 323.818 | J19: 392.735 | K19: 408.936 | L19: 431.924
A20: + Derivative & Hedging Assets | B20: BS_DERIV_HEDGING_ASST_ST | C20: 0 | D20: 0 | E20: 0 | F20: 0 | G20: 0 | H20: 0 | I20: 0 | J20: 0 | K20: 0 | L20: 0
A21: + Deferred Tax Assets | B21: BS_DEFERRED_TAX_ASSETS_ST | C21: 17.1 | D21: 19.7 | E21: — | F21: — | G21: — | H21: — | I21: — | J21: — | K21: — | L21: —
A22: + Misc ST Assets | B22: BS_OTHER_CUR_ASSET_LESS_PREPAY | C22: 3104.025 | D22: 3966.809 | E22: 4847.179 | F22: 5358.107 | G22: 524.669 | H22: 742.169 | I22: 913.883 | J22: 1826.388 | K22: 1084.257 | L22: 1749.412
A23: Total Current Assets | B23: BS_CUR_ASSET_REPORT | C23: 5431.84 | D23: 5720.291 | E23: 7669.974 | F23: 9694.135 | G23: 6178.504 | H23: 9761.58 | I23: 8069.825 | J23: 9266.473 | K23: 9918.133 | L23: 13100.379
A24: + Property, Plant & Equip, Net | B24: BS_NET_FIX_ASSET | C24: 173.412 | D24: 250.395 | E24: 319.404 | F24: 418.281 | G24: 2097.506 | H24: 2997.909 | I24: 3770.026 | J24: 3625.379 | K24: 3568.343 | L24: 3696.066
A25: + Property, Plant & Equip | B25: BS_GROSS_FIX_ASSET | C25: 470.758 | D25: 544.604 | E25: 641.218 | F25: 786.8 | G25: 2513.511 | H25: 3492.699 | I25: 4386.332 | J25: 4379.12 | K25: 4423.386 | L25: 4613.603
A26: - Accumulated Depreciation | B26: BS_ACCUM_DEPR | C26: 297.346 | D26: 294.209 | E26: 321.814 | F26: 368.519 | G26: 416.005 | H26: 494.79 | I26: 616.306 | J26: 753.741 | K26: 855.043 | L26: 917.537
A27: + LT Investments & Receivables | B27: BS_LT_INVEST | C27: 0 | D27: 0 | E27: 0 | F27: 0 | G27: 0 | H27: 0 | I27: 0 | J27: 0 | K27: 0 | L27: 0
A28: + Other LT Assets | B28: BS_OTHER_ASSETS_DEF_CHRG_OTHER | C28: 4597.619 | D28: 7615.924 | E28: 11023.364 | F28: 15861.984 | G28: 25699.702 | H28: 26520.87 | I28: 32744.812 | J28: 35702.916 | K28: 35245.516 | L28: 36833.929
A29: + Total Intangible Assets | B29: BS_DISCLOSED_INTANGIBLES | C29: 0 | D29: 0 | E29: 1469.654 | F29: 3616.968 | G29: 24504.567 | H29: 25383.95 | I29: 30919.539 | J29: 32736.713 | K29: 31658.056 | L29: 32452.462
A30: + Goodwill | B30: BS_GOODWILL | C30: 0 | D30: 0 | E30: 0 | F30: 0 | G30: 0 | H30: 0 | I30: 0 | J30: 0 | K30: 0 | L30: 0
A31: + Other Intangible Assets | B31: OTHER_INTANGIBLE_ASSETS_DETAILED | C31: 0 | D31: 0 | E31: 1469.654 | F31: 3616.968 | G31: 24504.567 | H31: 25383.95 | I31: 30919.539 | J31: 32736.713 | K31: 31658.056 | L31: 32452.462
A32: + Deferred Tax Assets | B32: BS_DEFERRED_TAX_ASSETS_LT | C32: 180.573 | D32: 227.248 | E32: 478.266 | F32: 564.425 | G32: 658.206 | H32: 589.091 | I32: 148.095 | J32: 261.541 | K32: 874.55 | L32: 1177.558
A33: + Derivative & Hedging Assets | B33: BS_DERIV_HEDGING_ASST_LT | C33: 0 | D33: 0 | E33: 0 | F33: 0 | G33: 0 | H33: 0 | I33: 0 | J33: 0 | K33: 0 | L33: 0
... A36: Total Assets | B36: BS_TOT_ASSET | C36: 10202.871 | D36: 13586.61 | E36: 19012.742 | F36: 25974.4 | G36: 33975.712 | H36: 39280.359 | I36: 44584.663 | J36: 48594.768 | K36: 48731.992 | L36: 53630.374
A38: Liabilities & Shareholders' Equity
A39: + Payables & Accruals | B39: ACCT_PAYABLE_ACCRUALS_DETAILED | C39: 393.88 | D39: 510.474 | E39: 674.649 | F39: 1044.859 | G39: 1326.768 | H39: 1502.157 | I39: 1971.645 | J39: 1830.178 | K39: 2168.06 | L39: 2627.971
A40: + Accounts Payable | B40: BS_ACCT_PAYABLE | C40: 253.491 | D40: 312.842 | E40: 359.555 | F40: 562.985 | G40: 674.347 | H40: 656.183 | I40: 837.483 | J40: 671.513 | K40: 747.412 | L40: 899.909
A41: + Accrued Taxes | B41: BS_TAXES_PAYABLE | C41: 0 | D41: 0 | E41: 0 | F41: 0 | G41: — | H41: — | I41: — | J41: — | K41: — | L41: —
A42: + Interest & Dividends Payable | B42: INTEREST_DIVIDENDS_PAYABLE | C42: 0 | D42: 0 | E42: 0 | F42: 0 | G42: — | H42: — | I42: — | J42: — | K42: — | L42: —
A43: + Other Payables & Accruals | B43: BS_ACCRUAL | C43: 140.389 | D43: 197.632 | E43: 315.094 | F43: 481.874 | G43: 652.421 | H43: 845.974 | I43: 1134.162 | J43: 1158.665 | K43: 1420.648 | L43: 1728.062
A44: + ST Debt | B44: BS_ST_BORROW | C44: 0 | D44: 0 | E44: 0 | F44: 0 | G44: 190.622 | H44: 756.1 | I44: 1015.012 | J44: 355.985 | K44: 783.156 | L44: 2212.935
A45: + ST Borrowings | B45: SHORT_TERM_DEBT_DETAILED | C45: 0 | D45: 0 | E45: 0 | F45: 0 | G45: 0 | H45: 499.878 | I45: 699.823 | J45: 0 | K45: 399.844 | L45: 1784.453
...

Sheet NFLX Cash Flow - Standardized
A2: Netflix Inc (NFLX US) - Standardized
A4: In Millions of USD except Per Share | C4: FY 2016 | D4: FY 2017 | E4: FY 2018 | F4: FY 2019 | G4: FY 2020 | H4: FY 2021 | I4: FY 2022 | J4: FY 2023 | K4: FY 2024 | L4: Last 12M
A5: 12 Months Ending | C5: 12/31/2016 | D5: 12/31/2017 | E5: 12/31/2018 | F5: 12/31/2019 | G5: 12/31/2020 | H5: 12/31/2021 | I5: 12/31/2022 | J5: 12/31/2023 | K5: 12/31/2024 | L5: 09/30/2025
A6: Cash from Operating Activities
A7: + Net Income | B7: CF_NET_INC | C7: 186.678 | D7: 558.929 | E7: 1211.242 | F7: 1866.916 | G7: 2761.395 | H7: 5116.228 | I7: 4491.924 | J7: 5407.99 | K7: 8711.631 | L7: 10431.287
A8: + Depreciation & Amortization | B8: CF_DEPR_AMORT | C8: 57.528 | D8: 71.911 | E8: 83.157 | F8: 103.579 | G8: 115.71 | H8: 208.412 | I8: 336.682 | J8: 356.947 | K8: 328.914 | L8: 326.945
A9: + Non-Cash Items | B9: NON_CASH_ITEMS_DETAILED | C9: -1962.864 | D9: -2488.911 | E9: -4266.583 | F9: -5023.391 | G9: -612.23 | H9: -4979.152 | I9: -2261.815 | J9: 1314.592 | K9: -2092.457 | L9: -1627.009
A10: + Stock-Based Compensation | B10: CF_STOCK_BASED_COMPENSATION | C10: 108.554 | D10: 182.209 | E10: 320.657 | F10: 405.376 | G10: 415.18 | H10: 403.22 | I10: 575.452 | J10: 339.368 | K10: 272.588 | L10: 295.652
A11: + Deferred Income Taxes | B11: CF_DEF_INC_TAX | C11: -46.847 | D11: -208.688 | E11: -85.52 | F11: -94.443 | G11: 70.066 | H11: 199.548 | I11: -166.55 | J11: -459.359 | K11: -590.698 | L11: -352.396
A12: + Other Non-Cash Adj | B12: OTHER_NON_CASH_ADJ_LESS_DETAILED | C12: -2024.571 | D12: -2462.432 | E12: -4501.72 | F12: -5334.324 | G12: -1097.476 | H12: -5581.92 | I12: -2670.717 | J12: 1434.583 | K12: -1774.347 | L12: -1570.265
A13: + Chg in Non-Cash Work Cap | B13: CF_CHNG_NON_CASH_WORK_CAP | C13: 244.674 | D13: 132.78 | E13: 291.705 | F13: 165.574 | G13: 162.202 | H13: 47.122 | I13: -540.534 | J13: 194.772 | K13: 413.276 | L13: 443.302
A14: + (Inc) Dec in Accts Receiv | B14: CF_ACCT_RCV_UNBILLED_REV | C14: 0 | D14: 0 | E14: 0 | F14: 0 | G14: 0 | H14: 0 | I14: 0 | J14: 0 | K14: 0 | L14: 0
A15: + (Inc) Dec in Inventories | B15: CF_CHANGE_IN_INVENTORIES | C15: 0 | D15: 0 | E15: 0 | F15: 0 | G15: 0 | H15: 0 | I15: 0 | J15: 0 | K15: 0 | L15: 0
A16: + Inc (Dec) in Accts Payable | B16: CF_CHANGE_IN_ACCOUNTS_PAYABLE | C16: 32.247 | D16: 74.559 | E16: 199.198 | F16: 96.063 | G16: -41.605 | H16: 145.115 | I16: -158.543 | J16: 93.502 | K16: 121.353 | L16: 129.45
A17: + Inc (Dec) in Other | B17: INC_DEC_IN_OT_OP_AST_LIAB_DETAIL | C17: 212.427 | D17: 58.221 | E17: 92.507 | F17: 69.511 | G17: 203.807 | H17: -97.993 | I17: -381.991 | J17: 101.27 | K17: 291.923 | L17: 313.852
A18: + Net Cash From Disc Ops | B18: CF_NET_CASH_DISCONT_OPS_OPER | C18: 0 | D18: 0 | E18: 0 | F18: 0 | G18: 0 | H18: 0 | I18: 0 | J18: 0 | K18: 0 | L18: 0
A19: Cash from Operating Activities | B19: CF_CASH_FROM_OPER | C19: -1473.984 | D19: -1725.291 | E19: -2680.479 | F19: -2887.322 | G19: 2427.077 | H19: 392.61 | I19: 2026.257 | J19: 7274.301 | K19: 7361.364 | L19: 9574.525
A21: Cash from Investing Activities
A22: + Change in Fixed & Intang | B22: FIXED_INTANG_ASST_CHANGE | C22: -184.83 | D22: -173.302 | E22: -173.946 | F22: -253.035 | G22: -497.923 | H22: -524.585 | I22: -407.729 | J22: -348.552 | K22: -439.538 | L22: -607.559
A23: + Disp in Fixed & Intang | B23: DISPOSAL_OF_FIXED_INTANG | C23: 0 | D23: 0 | E23: 0 | F23: 0 | G23: 0 | H23: 0 | I23: 0 | J23: 0 | K23: 0 | L23: 0
A24: + Disp of Fixed Prod Assets | B24: CF_DISPOSAL_OF_FIXED_PROD_ASSETS | C24: 0 | D24: 0 | E24: 0 | F24: 0 | G24: 0 | H24: 0 | I24: 0 | J24: 0 | K24: 0 | L24: 0
A25: + Disp of Intangible Assets | B25: CF_DISPOSAL_OF_INTANGIBLE_ASSETS | C25: 0 | D25: 0 | E25: 0 | F25: 0 | G25: 0 | H25: 0 | I25: 0 | J25: 0 | K25: 0 | L25: 0
A26: + Acq of Fixed & Intang | B26: ACQUIS_OF_FIXED_INTANG | C26: -184.83 | D26: -173.302 | E26: -173.946 | F26: -253.035 | G26: -497.923 | H26: -524.585 | I26: -407.729 | J26: -348.552 | K26: -439.538 | L26: -607.559
A27: + Acq of Fixed Prod Assets | B27: CF_PURCHASE_OF_FIXED_PROD_ASSETS | C27: -107.653 | D27: -173.302 | E27: -173.946 | F27: -253.035 | G27: -497.923 | H27: -524.585 | I27: -407.729 | J27: -348.552 | K27: -439.538 | L27: -607.559
A28: + Acq of Intangible Assets | B28: CF_ACQUISITION_OF_INTANG_ASSETS | C28: -77.177 | D28: 0 | E28: 0 | F28: 0 | G28: 0 | H28: 0 | I28: 0 | J28: 0 | K28: 0 | L28: 0
A29: + Net Change in LT Investment | B29: NET_CHG_IN_LT_INVEST_DETAILED | C29: 0 | D29: 0 | E29: 0 | F29: 0 | G29: 0 | H29: 0 | I29: 0 | J29: 0 | K29: 0 | L29: 0
A30: + Dec in LT Investment | B30: CF_DECR_INVEST | C30: 0 | D30: 0 | E30: 0 | F30: 0 | G30: 0 | H30: 0 | I30: 0 | J30: 0 | K30: 0 | L30: 0
A31: + Inc in LT Investment | B31: CF_INCR_INVEST | C31: 0 | D31: 0 | E31: 0 | F31: 0 | G31: 0 | H31: 0 | I31: 0 | J31: 0 | K31: 0 | L31: 0
A32: + Net Cash From Acq & Div | B32: CF_NT_CSH_RCVD_PD_FOR_ACQUIS_DIV | C32: 0 | D32: 0 | E32: 0 | F32: 0 | G32: 0 | H32: -788.349 | I32: -757.387 | J32: 0 | K32: 0 | L32: 0
A33: + Cash from Divestitures | B33: CF_CASH_FOR_DIVESTITURES | C33: 0 | D33: 0 | E33: 0 | F33: 0 | G33: 0 | H33: 0 | I33: 0 | J33: 0 | K33: 0 | L33: 0
... A38: Cash from Investing Activities | B38: CF_CASH_FROM_INV_ACT | C38: 49.765 | D38: 34.329 | E38: -339.12 | F38: -387.064 | G38: -505.354 | H38: -1339.853 | I38: -2076.392 | J38: 541.751 | K38: -2181.784 | L38: 1139.543
A40: Cash from Financing Activities
A41: + Dividends Paid | B41: CF_DVD_PAID | C41: 0 | D41: 0 | E41: 0 | F41: 0 | G41: 0 | H41: 0 | I41: 0 | J41: 0 | K41: 0 | L41: 0
A42: + Cash From (Repayment) Debt | B42: PROC_FR_REPAYMNTS_BOR_DETAILED | C42: 1000 | D42: 3020.51 | E42: 3961.852 | F42: 4469.306 | G42: 1009.464 | H42: -500 | I42: -700 | J42: 0 | K42: 1394.46 | L42: -38.99
A43: + Cash From (Repay) ST Debt | B43: CF_NET_CHG_ST_DEBT_CPTL_LEAS | C43: 0 | D43: 0 | E43: 0 | F43: 0 | G43: 0 | H43: 0 | I43: 0 | J43: 0 | K43: 0 | L43: 0
A44: + Cash From LT Debt | B44: CF_LT_DEBT_CAP_LEAS_PROCEEDS | C44: 1000 | D44: 3020.51 | E44: 3961.852 | F44: 4469.306 | G44: 1009.464 | H44: 0 | I44: 0 | J44: 0 | K44: 1794.46 | L44: 1794.46
A45: + Repayments of LT Debt | B45: CF_LT_DEBT_CAP_LEAS_PAYMENT | C45: 0 | D45: 0 | E45: 0 | F45: 0 | G45: 0 | H45: -500 | I45: -700 | J45: 0 | K45: -400 | L45: -1833.45
A46: + Cash (Repurchase) of Equity | B46: PROC_FR_REPURCH_EQTY_DETAILED | C46: 102.1 | D46: 88.378 | E46: 124.502 | F46: 72.49 | G46: 235.406 | H46: -649.776 | I46: 35.746 | J46: -5875.357 | K46: -5439.144 | L46: -7163.019
A47: + Increase in Capital Stock | B47: CF_INCR_CAP_STOCK | C47: 102.1 | D47: 88.378 | E47: 124.502 | F47: 72.49 | G47: 235.406 | H47: 174.414 | I47: 35.746 | J47: 169.99 | K47: 832.887 | L47: 892.895
A48: + Decrease in Capital Stock | B48: CF_DECR_CAP_STOCK | C48: 0 | D48: 0 | E48: 0 | F48: 0 | G48: 0 | H48: -824.19 | I48: 0 | J48: -6045.347 | K48: -6272.031 | L48: -8055.914
...

Sheet NFLX DDIS
A1: Security Id | B1: FIGI | C1: Maturity Type | D1: Security Description | E1: Maturity | F1: Principal Due | G1: Amount Outstanding | H1: Interest | I1: Coupon | J1: Currency | K1: Normalized Payment Rank | L1: Ask Price | M1: Yield to Maturity (Mid)
A2: QZ981474 Corp | B2: BBG00F2Y0L02 | C2: AT MATURITY | D2: NFLX 4 3/8 11/15/26 | E2: 11/15/2026 | F2: 1000000000 | G2: 1000000000 | H2: 43750000 | I2: 4.375 | J2: USD | K2: Sr Unsecured | L2: 100.528 | M2: 3.8499429
A3: AN303464 Corp | B3: BBG00GH97FL2 | C3: AT MATURITY | D3: NFLX 3 5/8 05/15/27 | E3: 5/15/2027 | F3: 1513070000 | G3: =1.17*1300000000 -> 1521000000 | H3: 82273181 | I3: 3.625 | J3: EUR | K3: Sr Unsecured | L3: =1.17*101.609 -> 118.88253 | M3: 2.544718
A4: AP697039 Corp | B4: BBG00J200JG6 | C4: AT MATURITY | D4: NFLX 4 7/8 04/15/28 | E4: 4/15/2028 | F4: 1600000000 | G4: 1600000000 | H4: 195000000 | I4: 4.875 | J4: USD | K4: Sr Unsecured | L4: 101.993 | M4: 3.9991234
A5: AS350093 Corp | B5: BBG00KR6JFD4 | C5: AT MATURITY | D5: NFLX 5 7/8 11/15/28 | E5: 11/15/2028 | F5: 1900000000 | G5: 1900000000 | H5: 334875000 | I5: 5.875 | J5: USD | K5: Sr Unsecured | L5: 105.113 | M5: 4.0241076
A6: AV183514 Corp | B6: BBG00MC44D79 | C6: AT MATURITY | D6: NFLX 6 3/8 05/15/29 | E6: 5/15/2029 | F6: 800000000 | G6: 800000000 | H6: 178500000 | I6: 6.375 | J6: USD | K6: Sr Unsecured | L6: 107.18 | M6: 4.1245108
A7: AV183443 Corp | B7: BBG00MC43VH9 | C7: AT MATURITY | D7: NFLX 4 5/8 05/15/29 | E7: 5/15/2029 | F7: 1280290000 | G7: =1.17*1100000000 -> 1287000000 | H7: 2.0724694e+08 | I7: 4.625 | J7: EUR | K7: Sr Unsecured | L7: =1.17*105.57 -> 123.5169 | M7: 2.9645392
A8: ZS293068 Corp | B8: BBG00NZKTXY5 | C8: AT MATURITY | D8: NFLX 5 3/8 11/15/29 | E8: 11/15/2029 | F8: 900000000 | G8: 900000000 | H8: 213656250 | I8: 5.375 | J8: USD | K8: Sr Unsecured | L8: 104.213 | M8: 4.2131188
A9: ZS293842 Corp | B9: BBG00NZKW073 | C9: AT MATURITY | D9: NFLX 3 7/8 11/15/29 | E9: 11/15/2029 | F9: 1396680000 | G9: =1.17*1200000000 -> 1404000000 | H9: 2.3903596e+08 | I9: 3.875 | J9: EUR | K9: Sr Unsecured | L9: =1.17*103.296 -> 120.85632 | M9: 3.0356056
A10: ZQ225580 Corp | B10: BBG00QN4ND86 | C10: CALLABLE | D10: NFLX 4 7/8 06/15/30 | E10: 6/15/2030 | F10: 1000000000 | G10: 1000000000 | H10: 243750000 | I10: 4.875 | J10: USD | K10: Sr Unsecured | L10: 102.333 | M10: 4.3109543
A11: ZQ233908 Corp | B11: BBG00QN8NCJ7 | C11: CALLABLE | D11: NFLX 3 5/8 06/15/30 | E11: 6/15/2030 | F11: 1280290000 | G11: =1.17*1100000000 -> 1287000000 | H11: 2.3205256e+08 | I11: 3.625 | J11: EUR | K11: Sr Unsecured | L11: =1.17*102.303 -> 119.69451 | M11: 3.1199597
A12: YW769976 Corp | B12: BBG01P177GC0 | C12: CALLABLE | D12: NFLX 4.9 08/15/34 | E12: 8/15/2034 | F12: 1000000000 | G12: 1000000000 | H12: 441000000 | I12: 4.9 | J12: USD | K12: Sr Unsecured | L12: 102.463 | M12: 4.559715
A13: YW769977 Corp | B13: BBG01P177GH5 | C13: CALLABLE | D13: NFLX 5.4 08/15/54 | E13: 8/15/2054 | F13: 800000000 | G13: 800000000 | H13: 1252800000 | I13: 5.4 | J13: USD | K13: Sr Unsecured | L13: 97.836 | M13: 5.5611686
C16: Total Debt | D16: =SUMPRODUCT(G2:G13,L2:L13,M2:M13)/10000 -> 5.8628481e+08
C17: Debt Outstanding | D17: =SUMPRODUCT(G2:G13,L2:L13)/100 -> 1.5895477e+10
C18: CoD | D18: =D16/D17 -> 0.036883751

Sheet PSKY Income Statement - GAAP 
A2: Paramount Skydance Corp (PSKY US) - BBG GAAP
A4: In Millions of USD except Per Share | C4: FY 2023 | D4: FY 2024 | E4: Last 12M | F4: FY 2025 Est | G4: FY 2026 Est
A5: 12 Months Ending | C5: 12/31/2023 | D5: 12/31/2024 | E5: 09/30/2025 | F5: 12/31/2025 | G5: 12/31/2026
A6: Revenue | B6: SALES_REV_TURN | C6: 29652 | D6: 29213 | E6: 28727 | F6: 28954.389 | G6: 29969.778
A7: + Sales & Services Revenue | B7: IS_SALES_AND_SERVICES_REVENUES | C7: 23007 | D7: 23448 | E7: 24289
A8: + Other Revenue | B8: IS_OTHER_REVENUE | C8: 6645 | D8: 5765
A9: - Cost of Revenue | B9: IS_COGS_TO_FE_AND_PP_AND_G | C9: 20017 | D9: 19437 | E9: 19620
A10: + Cost of Goods & Services | B10: IS_COG_AND_SERVICES_SOLD | C10: 20017 | D10: 19437 | E10: 19620
A11: Gross Profit | B11: GROSS_PROFIT | C11: 9635 | D11: 9776 | E11: 9107 | F11: 2924.3933 | G11: 3543.6265
A12: + Other Operating Income | B12: IS_OTHER_OPER_INC | C12: 0 | D12: 0 | E12: 0
A13: - Operating Expenses | B13: IS_OPERATING_EXPN | C13: 10086 | D13: 15045 | E13: 7705
A14: + Selling, General & Admin | B14: IS_SGA_EXPENSE | C14: 7245 | D14: 6658 | E14: 6237
A15: + Research & Development | B15: IS_OPER_EXPENSES_RD_GAAP | C15: 0 | D15: —
A16: + Depreciation & Amortization | B16: IS_DEPRECIATION_AND_AMORTIZATION | C16: 418 | D16: 392 | E16: 525
A17: + Other Operating Expense | B17: OTHER_OPERATING_EXPENSES_RATIO | C17: 2423 | D17: 7995 | E17: 943
A18: Operating Income (Loss) | B18: IS_OPER_INC | C18: -451 | D18: -5269 | E18: 1402 | F18: 2188.7778 | G18: 2412.3
A19: - Non-Operating (Income) Loss | B19: NONOP_INCOME_LOSS | C19: 802 | D19: 908 | E19: 891
A20: + Interest Expense, Net | B20: IS_NET_INTEREST_EXPENSE | C20: 783 | D20: 709 | E20: 722
A21: + Interest Expense | B21: IS_INT_EXPENSE | C21: 920 | D21: 860 | E21: 869
A22: - Interest Income | B22: IS_INT_INC | C22: 137 | D22: 151 | E22: 147
A23: + Foreign Exch (Gain) Loss | B23: IS_FOREIGN_EXCH_LOSS | C23: 0 | D23: 0
A24: + Other Non-Op (Income) Loss | B24: OTHER_NONOP_INCOME_LOSS | C24: 19 | D24: 199 | E24: 169
A25: Pretax Income | B25: PRETAX_INC | C25: -1253 | D25: -6177 | E25: 511 | F25: 678.364 | G25: 1371.133
A26: - Income Tax Expense (Benefit) | B26: IS_INC_TAX_EXP | C26: -361 | D26: -305 | E26: 43
A27: + Current Income Tax | B27: IS_CURRENT_INCOME_TAX_BENEFIT | C27: 289 | D27: 325
A28: + Deferred Income Tax | B28: IS_DEFERRED_INCOME_TAX_BENEFIT | C28: -650 | D28: -630
A29: - (Income) Loss from Affiliates | B29: IS_SH_PRO_EQY_MT_INV_NET_OF_TAX | C29: 360 | D29: 291 | E29: 274
A30: Income (Loss) from Cont Ops | B30: IS_INC_BEF_XO_ITEM | C30: -1252 | D30: -6163 | E30: 194 | F30: -296.462 | G30: 620.746
A31: - Net Extraordinary Losses (Gains) | B31: XO_GL_NET_OF_TAX | C31: -676 | D31: -14 | E31: 0
A32: + Discontinued Operations | B32: IS_DISCONTINUED_OPERATIONS | C32: -676 | D32: -14 | E32: 0
A33: + XO & Accounting Changes | B33: EXTRAORD_ITEMS_ACCOUNTING_CHANGS | C33: 0 | D33: 0 | E33: 0
A34: Income (Loss) Incl. MI | B34: NI_INCLUDING_MINORITY_INT_RATIO | C34: -576 | D34: -6149 | E34: 194
A35: - Minority Interest | B35: MIN_NONCONTROL_INTEREST_CREDITS | C35: 32 | D35: 41 | E35: 466
A36: Net Income, GAAP | B36: NET_INCOME | C36: -608 | D36: -6190 | E36: -272 | F36: -296.462 | G36: 620.746
A37: - Preferred Dividends | B37: IS_TOT_CASH_PFD_DVD | C37: 0 | D37: 0 | E37: 0
A38: - Other Adjustments | B38: OTHER_ADJUSTMENTS | C38: 0 | D38: 0 | E38: 0
A39: Net Income Avail to Common, GAAP | B39: EARN_FOR_COMMON | C39: -608 | D39: -6190 | E39: -272 | F39: -296.462 | G39: 620.746
A41: Net Income Avail to Common, Adj | B41: EARN_FOR_COMMON | C41: 400 | D41: 1041 | E41: 919.81 | F41: 248.889 | G41: 1009.333
A42: Net Abnormal Losses (Gains) | B42: IS_NET_ABNORMAL_ITEMS | C42: 1684 | D42: 7245 | E42: 1191.81
A43: Net Extraordinary Losses (Gains) | B43: XO_GL_NET_OF_TAX | C43: -676 | D43: -14 | E43: 0
...

Sheet PSKY Balance Sheet
A2: Paramount Skydance Corp (PSKY US) - Standardized
A4: In Millions of USD except Per Share | C4: FY 2023 | D4: FY 2024
A5: 12 Months Ending | C5: 12/31/2023 | D5: 12/31/2024
A6: Total Assets
A7: + Cash, Cash Equivalents & STI | B7: CASH_CASH_EQTY_STI_DETAILED | C7: 2460 | D7: 2661
A8: + Cash & Cash Equivalents | B8: BS_CASH_NEAR_CASH_ITEM | C8: 2460 | D8: 2661
A9: + ST Investments | B9: BS_MKT_SEC_OTHER_ST_INVEST | C9: 0 | D9: 0
A10: + Accounts & Notes Receiv | B10: BS_ACCT_NOTE_RCV | C10: 7115 | D10: 6920
A11: + Accounts Receivable, Net | B11: BS_ACCTS_REC_EXCL_NOTES_REC | C11: 7115 | D11: 6920
A12: + Inventories | B12: BS_INVENTORIES | C12: 1414 | D12: 1429
A13: + Other ST Assets | B13: OTHER_CURRENT_ASSETS_DETAILED | C13: 1714 | D13: 1532
A14: + Prepaid Expenses | B14: BS_PREPAY | C14: 1677 | D14: 1532
A15: + Discontinued Operations | B15: BS_ASSETS_OF_DISCONTINUED_OPS_ST | C15: 37 | D15: 0
A16: + Misc ST Assets | B16: BS_OTHER_CUR_ASSET_LESS_PREPAY | C16: 0 | D16: 0
A17: Total Current Assets | B17: BS_CUR_ASSET_REPORT | C17: 12703 | D17: 12542
A18: + Property, Plant & Equip, Net | B18: BS_NET_FIX_ASSET | C18: 2849 | D18: 2578
... A28: + Derivative & Hedging Assets | B28: BS_DERIV_HEDGING_ASST_LT | C28: 0 | D28: 0
A29: + Discontinued Operations | B29: BS_ASSETS_OF_DISCONTINUED_OPS_LT | C29: — | D29: 0
A30: + Misc LT Assets | B30: OTHER_NONCURRENT_ASSETS_DETAILED | C30: 17322 | D30: 16426
A31: Total Noncurrent Assets | B31: BS_TOT_NON_CUR_ASSET | C31: 40840 | D31: 33630
A32: Total Assets | B32: BS_TOT_ASSET | C32: 53543 | D32: 46172
A34: Liabilities & Shareholders' Equity
A35: + Payables & Accruals | B35: ACCT_PAYABLE_ACCRUALS_DETAILED | C35: 3204 | D35: 3152
A36: + Accounts Payable | B36: BS_ACCT_PAYABLE | C36: 1100 | D36: 953
A37: + Other Payables & Accruals | B37: BS_ACCRUAL | C37: 2104 | D37: 2199
A38: + ST Debt | B38: BS_ST_BORROW | C38: 1 | D38: 0
A39: + ST Borrowings | B39: SHORT_TERM_DEBT_DETAILED | C39: 0 | D39: 0
A40: + ST Lease Liabilities | B40: ST_CAPITALIZED_LEASE_LIABILITIES | C40: 0 | D40: —
A41: + ST Finance Leases | B41: ST_CAPITAL_LEASE_OBLIGATIONS | C41: 0 | D41: —
A42: + Current Portion of LT Debt | B42: BS_CURR_PORTION_LT_DEBT | C42: 1 | D42: 0
A43: + Other ST Liabilities | B43: OTHER_CURRENT_LIABS_SUB_DETAILED | C43: 6451 | D43: 6479
A44: + Deferred Revenue | B44: ST_DEFERRED_REVENUE | C44: 746 | D44: 825
A45: + Misc ST Liabilities | B45: OTHER_CURRENT_LIABS_DETAILED | C45: 5705 | D45: 5654
A46: Total Current Liabilities | B46: BS_CUR_LIAB | C46: 9656 | D46: 9631
A47: + LT Debt | B47: BS_LT_BORROW | C47: 15857 | D47: 15549
A48: + LT Borrowings | B48: LONG_TERM_BORROWINGS_DETAILED | C48: 14601 | D48: 14501
A49: + LT Lease Liabilities | B49: LT_CAPITALIZED_LEASE_LIABILITIES | C49: 1256 | D49: 1048
A50: + LT Finance Leases | B50: LT_CAPITAL_LEASE_OBLIGATIONS | C50: 0 | D50: —
A51: + LT Operating Leases | B51: BS_LT_OPERATING_LEASE_LIABS | C51: 1256 | D51: 1048
A52: + Other LT Liabilities | B52: OTHER_NONCUR_LIABS_SUB_DETAILED | C52: 4980 | D52: 4210
...

Sheet PSKY Cash Flow - Standardized
A2: Paramount Skydance Corp (PSKY US) - Standardized
A4: In Millions of USD except Per Share | C4: FY 2023 | D4: FY 2024 | E4: Last 12M
A5: 12 Months Ending | C5: 12/31/2023 | D5: 12/31/2024 | E5: 09/30/2025
A6: Cash from Operating Activities
A7: + Net Income | B7: CF_NET_INC | C7: -608 | D7: -6190 | E7: -272
A8: + Depreciation & Amortization | B8: CF_DEPR_AMORT | C8: 418 | D8: 392 | E8: 525
A9: + Non-Cash Items | B9: NON_CASH_ITEMS_DETAILED | C9: 16216 | D9: 21099 | E9: 14667
A10: + Stock-Based Compensation | B10: CF_STOCK_BASED_COMPENSATION | C10: 177 | D10: 245 | E10: 242
A11: + Deferred Income Taxes | B11: CF_DEF_INC_TAX | C11: -650 | D11: -630 | E11: -382
A12: + Other Non-Cash Adj | B12: OTHER_NON_CASH_ADJ_LESS_DETAILED | C12: 16689 | D12: 21484 | E12: 14807
A13: + Chg in Non-Cash Work Cap | B13: CF_CHNG_NON_CASH_WORK_CAP | C13: -15642 | D13: -14549
A14: + (Inc) Dec in Accts Receiv | B14: CF_ACCT_RCV_UNBILLED_REV | C14: 523 | D14: 548
A15: + (Inc) Dec in Inventories | B15: CF_CHANGE_IN_INVENTORIES | C15: -15518 | D15: -15812
A16: + Inc (Dec) in Other | B16: INC_DEC_IN_OT_OP_AST_LIAB_DETAIL | C16: -647 | D16: 715 | E16: -14320
A17: + Net Cash From Disc Ops | B17: CF_NET_CASH_DISCONT_OPS_OPER | C17: 91 | D17: 0
A18: Cash from Operating Activities | B18: CF_CASH_FROM_OPER | C18: 475 | D18: 752 | E18: 600
A20: Cash from Investing Activities
A21: + Change in Fixed & Intang | B21: FIXED_INTANG_ASST_CHANGE | C21: -257 | D21: 291 | E21: 333
A22: + Disp in Fixed & Intang | B22: DISPOSAL_OF_FIXED_INTANG | C22: 71 | D22: 554 | E22: 625
A23: + Disp of Fixed Prod Assets | B23: CF_DISPOSAL_OF_FIXED_PROD_ASSETS | C23: 71 | D23: 554 | E23: 625
A24: + Disp of Intangible Assets | B24: CF_DISPOSAL_OF_INTANGIBLE_ASSETS | C24: 0 | D24: 0 | E24: 0
A25: + Acq of Fixed & Intang | B25: ACQUIS_OF_FIXED_INTANG | C25: -328 | D25: -263 | E25: -292
A26: + Acq of Fixed Prod Assets | B26: CF_PURCHASE_OF_FIXED_PROD_ASSETS | C26: -328 | D26: -263 | E26: -292
A27: + Acq of Intangible Assets | B27: CF_ACQUISITION_OF_INTANG_ASSETS | C27: 0 | D27: 0 | E27: 0
A28: + Net Change in LT Investment | B28: NET_CHG_IN_LT_INVEST_DETAILED | C28: — | D28: — | E28: -206
A29: + Net Cash From Acq & Div | B29: CF_NT_CSH_RCVD_PD_FOR_ACQUIS_DIV | C29: 0 | D29: 0 | E29: 0
A30: + Cash from Divestitures | B30: CF_CASH_FOR_DIVESTITURES | C30: 0 | D30: 0 | E30: 0
A31: + Cash for Acq of Subs | B31: CF_CASH_FOR_ACQUIS_SUBSIDIARIES | C31: 0 | D31: 0 | E31: 0
A32: + Cash for JVs | B32: CF_CASH_FOR_JOINT_VENTURES_ASSOC | C32: 0 | D32: 0 | E32: 0
A33: + Other Investing Activities | B33: OTHER_INVESTING_ACT_DETAILED | C33: -325 | D33: -334 | E33: -123
A34: + Net Cash From Disc Ops | B34: CF_NET_CASH_DISCONTINUED_OPS_INV | C34: 1524 | D34: 55 | E34: 7
A35: Cash from Investing Activities | B35: CF_CASH_FROM_INV_ACT | C35: 942 | D35: 12 | E35: 11
A37: Cash from Financing Activities
A38: + Dividends Paid | B38: CF_DVD_PAID | C38: -447 | D38: -168 | E38: -171
A39: + Cash From (Repayment) Debt | B39: PROC_FR_REPAYMNTS_BOR_DETAILED | C39: -1232 | D39: -126 | E39: -126
A40: + Cash From (Repay) ST Debt | B40: CF_NET_CHG_ST_DEBT_CPTL_LEAS | C40: — | D40: — | E40: 0
A41: + Cash From LT Debt | B41: CF_LT_DEBT_CAP_LEAS_PROCEEDS | C41: 45 | D41: 0 | E41: 0
A42: + Repayments of LT Debt | B42: CF_LT_DEBT_CAP_LEAS_PAYMENT | C42: -1277 | D42: -126 | E42: -126
A43: + Cash (Repurchase) of Equity | B43: PROC_FR_REPURCH_EQTY_DETAILED | C43: 0 | D43: 0 | E43: 0
A44: + Increase in Capital Stock | B44: CF_INCR_CAP_STOCK | C44: 0 | D44: 0 | E44: 0
...

Sheet PSKY DDIS
A1: Security Id | B1: FIGI | C1: Maturity Type | D1: Security Description | E1: Maturity | F1: Principal Due | G1: Amount Outstanding | H1: Interest | I1: Coupon | J1: Currency | K1: Normalized Payment Rank | L1: Ask Price | M1: Yield to Maturity (Mid)
A2: AF209530 Corp | B2: BBG009KBRDY8 | C2: CALLABLE | D2: PARA 4 01/15/26 | E2: 1/15/2026 | F2: 346688000 | G2: 346688000 | H2: 6933760 | I2: 4 | J2: USD | K2: Sr Unsecured | L2: 99.873 | M2: 5.5910754
A3: QZ739372 Corp | B3: BBG00DY2TDD5 | C3: CALLABLE | D3: PARA 3.45 10/04/26 | E3: 10/4/2026 | F3: 86023000 | G3: 86023000 | H3: 3182851 | I3: 3.7 | J3: USD | K3: Sr Unsecured | L3: 99.192 | M3: 4.9659423
A4: LW785817 Corp | B4: BBG00D8Y5Q41 | C4: CALLABLE | D4: PARA 2.9 01/15/27 | E4: 1/15/2027 | F4: 584271000 | G4: 584271000 | H4: 25415788 | I4: 2.9 | J4: USD | K4: Sr Unsecured | L4: 98.328 | M4: 4.5717154
A5: AO125940 Corp | B5: BBG00H1J1TV0 | C5: CALLABLE | D5: PARA 3 3/8 02/15/28 | E5: 2/15/2028 | F5: 500000000 | G5: 500000000 | H5: 42187500 | I5: 3.375 | J5: USD | K5: Sr Unsecured | L5: 97.502 | M5: 4.6292155
A6: AQ010221 Corp | B6: BBG00J7940J6 | C6: CALLABLE | D6: PARA 3.7 06/01/28 | E6: 6/1/2028 | F6: 6000000 | G6: 6000000 | H6: 555000 | I6: 3.7 | J6: USD | K6: Sr Unsecured | L6: 98.063 | M6: 4.6047152
A7: AV620013 Corp | B7: BBG00MJH2WG3 | C7: CALLABLE | D7: PARA 3.7 06/01/28 | E7: 6/1/2028 | F7: 494000000 | G7: 494000000 | H7: 45695000 | I7: 3.7 | J7: USD | K7: Sr Unsecured | L7: 98.063 | M7: 4.6047152
A8: AX333946 Corp | B8: BBG00NDXY371 | C8: CALLABLE | D8: PARA 4.2 06/01/29 | E8: 6/1/2029 | F8: 500000000 | G8: 500000000 | H8: 73500000 | I8: 4.2 | J8: USD | K8: Sr Unsecured | L8: 97.791 | M8: 4.9285379
A9: EC278276 Corp | B9: BBG00000WL60 | C9: AT MATURITY | D9: PARA 7 7/8 07/30/30 | E9: 7/30/2030 | F9: 826813000 | G9: 826813000 | H9: 3.2555762e+08 | I9: 7.875 | J9: USD | K9: Sr Unsecured | L9: 109.912 | M9: 5.4697485
A10: BH428437 Corp | B10: BBG00SW8BQR6 | C10: CALLABLE | D10: PARA 4.95 01/15/31 | E10: 1/15/2031 | F10: 1250000000 | G10: 1250000000 | H10: 340312500 | I10: 4.95 | J10: USD | K10: Sr Unsecured | L10: 97.389 | M10: 5.5604712
A11: BJ450828 Corp | B11: BBG00TSW2BF2 | C11: CALLABLE | D11: PARA 4.2 05/19/32 | E11: 5/19/2032 | F11: 1000000000 | G11: 1000000000 | H11: 273000000 | I11: 4.2 | J11: USD | K11: Sr Unsecured | L11: 92.035 | M11: 5.7185216
A12: EC972767 Corp | B12: BBG00007SFJ9 | C12: AT MATURITY | D12: PARA 5 1/2 05/15/33 | E12: 5/15/2033 | F12: 430513000 | G12: 430513000 | H12: 1.7758661e+08 | I12: 5.5 | J12: USD | K12: Sr Unsecured | L12: 95.829 | M12: 6.2473692
A13: EK641114 Corp | B13: BBG007NS0QC6 | C13: CALLABLE | D13: PARA 4.85 12/15/34 | E13: 12/15/2034 | F13: 87397000 | G13: 87397000 | H13: 40268168 | I13: 4.85 | J13: USD | K13: Sr Unsecured | L13: 87.478 | M13: 6.7912133
... A27: BV521066 Corp | B27: BBG016C3H9C4 | C27: CALLABLE | D27: PARA 6 3/8 03/30/62 | E27: 3/30/2062 | F27: 1000000000 | G27: 1000000000 | H27: 3005775000 | I27: 6.375 | J27: USD | K27: Jr Subordinated Unsecured | L27: 97.085 | M27: 8.1463809
A31: Total Cost of Debt | B31: =SUMPRODUCT(M2:M27,G2:G27,L2:L27)/10000 -> 8.7376923e+08
A32: Debt Outstanding | B32: =SUMPRODUCT(L2:L27,G2:G27)/100 -> 1.3483497e+10
A33: CoD | B33: =B31/B32 -> 0.064802865

Sheet WBD Income Statement - GAAP
A2: Warner Bros Discovery Inc (WBD US) - BBG GAAP
A4: In Millions of USD except Per Share | B4: FY 2018 | C4: FY 2019 | D4: FY 2020 | E4: FY 2021 | F4: FY 2022 | G4: FY 2023 | H4: FY 2024 | I4: Last 12M | J4: FY 2025 Est | K4: FY 2026 Est
A5: 12 Months Ending | B5: 43465 | C5: 43830 | D5: 44196 | E5: 44561 | F5: 44926 | G5: 45291 | H5: 45657 | I5: 45930 | J5: 46022 | K5: 46387
A6: Revenue | B6: 10553 | C6: 11144 | D6: 10671 | E6: 12191 | F6: 33817 | G6: 41321 | H6: 39321 | I6: 37863 | J6: 37173.5 | K6: 36867.5
A7: + Sales & Services Revenue | B7: 10052 | C7: 10879 | D7: 10449 | E7: 11624 | F7: 24666 | G7: 28937 | H7: 27791 | I7: 26823
A8: + Other Revenue | B8: 501 | C8: 265 | D8: 222 | E8: 567 | F8: 9151 | G8: 12384 | H8: 11530 | I8: 11040
A9: - Cost of Revenue | B9: 3935 | C9: 3819 | D9: 3860 | E9: 4620 | F9: 20442 | G9: 24526 | H9: 22970 | I9: 21189
A10: + Cost of Goods & Services | B10: 3935 | C10: 3819 | D10: 3860 | E10: 4620 | F10: 20442 | G10: 24526 | H10: 22970 | I10: 21189
A11: Gross Profit | B11: 6618 | C11: 7325 | D11: 6811 | E11: 7571 | F11: 13375 | G11: 16795 | H11: 16351 | I11: 16674 | J11: 14037.8 | K11: 14949.8
A12: + Other Operating Income | B12: 0 | C12: 0 | D12: 0 | E12: 0 | F12: 0 | G12: 0 | H12: 0 | I12: 0
A13: - Operating Expenses | B13: 4684 | C13: 4316 | D13: 4296 | E13: 5559 | F13: 20745 | G13: 18343 | H13: 26383 | I13: 16123
A14: + Selling, General & Admin | B14: 2620 | C14: 2788 | D14: 2722 | E14: 4016 | F14: 9678 | G14: 9696 | H14: 9296 | I14: 9250
A15: + Research & Development | B15: — | C15: 0 | D15: 0 | E15: 0 | F15: 0 | G15: 0 | H15: 0
A16: + Depreciation & Amortization | B16: 1398 | C16: 1347 | D16: 1359 | E16: 1582 | F16: 7193 | G16: 7985 | H16: 7037 | I16: 6012
A17: + Other Operating Expense | B17: 666 | C17: 181 | D17: 215 | E17: -39 | F17: 3874 | G17: 662 | H17: 10050 | I17: 861
A18: Operating Income (Loss) | B18: 1934 | C18: 3009 | D18: 2515 | E18: 2012 | F18: -7370 | G18: -1548 | H18: -10032 | I18: 551 | J18: 1171.7 | K18: 1848.4
A19: - Non-Operating (Income) Loss | B19: 912 | C19: 715 | D19: 787 | E19: 579 | F19: 1590 | G19: 2315 | H19: 1356 | I19: -1140
A20: + Interest Expense, Net | B20: 729 | C20: 677 | D20: 648 | E20: 633 | F20: 1777 | G20: 2221 | H20: 2017 | I20: 1991
A21: + Interest Expense | B21: 733 | C21: 678 | D21: 648 | E21: 651 | F21: 1777 | G21: 2221 | H21: 2017 | I21: 1991
A22: - Interest Income | B22: 4 | C22: 1 | D22: 0 | E22: 18 | F22: 0 | G22: 0 | H22: 0 | I22: 0
A23: + Foreign Exch (Gain) Loss | B23: 93 | C23: -17 | D23: 115 | E23: -93 | F23: -150 | G23: -173 | H23: -323 | I23: 182
A24: + (Income) Loss from Affiliates | B24: 63 | C24: 2 | D24: 105 | E24: 18 | F24: 160 | G24: 82 | H24: 121 | I24: 17
A25: + Other Non-Op (Income) Loss | B25: 27 | C25: 53 | D25: -81 | E25: 21 | F25: -197 | G25: 185 | H25: -459 | I25: -3330
A26: Pretax Income | B26: 1022 | C26: 2294 | D26: 1728 | E26: 1433 | F26: -8960 | G26: -3863 | H26: -11388 | I26: 1691 | J26: 1990.5 | K26: 252.5
A27: - Income Tax Expense (Benefit) | B27: 341 | C27: 81 | D27: 373 | E27: 236 | F27: -1663 | G27: -784 | H27: 94 | I27: 1335
B28: =B27/B26 -> 0.33365949 | C28: =C27/C26 -> 0.035309503 | D28: =D27/D26 -> 0.21585648 | E28: =E27/E26 -> 0.16468946 | F28: =F27/F26 -> 0.18560268 | G28: =G27/G26 -> 0.20295107 | H28: =H27/H26 -> -0.0082543028
A29: + Current Income Tax | B29: 472 | C29: 585 | D29: 559 | E29: 747 | F29: 1179 | G29: 1560 | H29: 1826
A30: + Deferred Income Tax | B30: -131 | C30: -504 | D30: -186 | E30: -511 | F30: -2842 | G30: -2344 | H30: -1732
A31: Income (Loss) from Cont Ops | B31: 681 | C31: 2213 | D31: 1355 | E31: 1197 | F31: -7297 | G31: -3079 | H31: -11482 | I31: 356 | J31: 931.3 | K31: 70.5
A32: - Net Extraordinary Losses (Gains) | B32: 0 | C32: 0 | D32: 0 | E32: 0 | F32: 0 | G32: 0 | H32: 0 | I32: 0
A33: + Discontinued Operations | B33: 0 | C33: 0 | D33: 0 | E33: 0 | F33: 0 | G33: 0 | H33: 0 | I33: 0
A34: + XO & Accounting Changes | B34: 0 | C34: 0 | D34: 0 | E34: 0 | F34: 0 | G34: 0 | H34: 0 | I34: 0
A35: Income (Loss) Incl. MI | B35: 681 | C35: 2213 | D35: 1355 | E35: 1197 | F35: -7297 | G35: -3079 | H35: -11482 | I35: 356
A36: - Minority Interest | B36: 87 | C36: 144 | D36: 136 | E36: 191 | F36: 74 | G36: 47 | H36: -171 | I36: -129
A37: Net Income, GAAP | B37: 594 | C37: 2069 | D37: 1219 | E37: 1006 | F37: -7371 | G37: -3126 | H37: -11311 | I37: 485 | J37: 931.3 | K37: 70.5
A38: - Preferred Dividends | B38: 60 | C38: 204 | D38: 128 | E38: 110 | F38: 49 | G38: 0 | H38: 0 | I38: 0
A39: - Other Adjustments | B39: 105 | C39: 314 | D39: 172 | E39: 116 | F39: 0 | G39: 0 | H39: 0 | I39: 0
A40: Net Income Avail to Common, GAAP | B40: 429 | C40: 1551 | D40: 919 | E40: 780 | F40: -7420 | G40: -3126 | H40: -11311 | I40: 485 | J40: 931.3 | K40: 70.5
A42: Net Income Avail to Common, Adj | B42: 1066.3 | C42: 1746.3 | D42: 1155.2 | E42: 884.3 | F42: -3572.7 | G42: -2449.8 | H42: -4035.1 | I42: -1046 | J42: 1002.5 | K42: -225
A43: Net Abnormal Losses (Gains) | B43: 637.3 | C43: 195.3 | D43: 236.2 | E43: 104.3 | F43: 3847.3 | G43: 676.2 | H43: 7275.9 | I43: -1531
...

Sheet WBD Balance Sheet
A2: Warner Bros Discovery Inc (WBD US) - Standardized
A4: In Millions of USD except Per Share | B4: FY 2015 | C4: FY 2016 | D4: FY 2017 | E4: FY 2018 | F4: FY 2019 | G4: FY 2020 | H4: FY 2021 | I4: FY 2022 | J4: FY 2023 | K4: FY 2024
A5: 12 Months Ending | B5: 42369 | C5: 42735 | D5: 43100 | E5: 43465 | F5: 43830 | G5: 44196 | H5: 44561 | I5: 44926 | J5: 45291 | K5: 45657
A6: Total Assets
A7: + Cash, Cash Equivalents & STI | B7: 390 | C7: 300 | D7: 7309 | E7: 986 | F7: 1552 | G7: 2091 | H7: 3905 | I7: 3731 | J7: 3780 | K7: 5312
A8: + Cash & Cash Equivalents | B8: 390 | C8: 300 | D8: 7309 | E8: 986 | F8: 1552 | G8: 2091 | H8: 3905 | I8: 3731 | J8: 3780 | K8: 5312
A9: + ST Investments | B9: 0 | C9: 0 | D9: 0 | E9: 0 | F9: 0 | G9: 0 | H9: 0 | I9: 0 | J9: 0 | K9: 0
A10: + Accounts & Notes Receiv | B10: 1479 | C10: 1495 | D10: 1838 | E10: 2620 | F10: 2633 | G10: 2537 | H10: 2446 | I10: 6380 | J10: 6047 | K10: 4947
A11: + Accounts Receivable, Net | B11: 1479 | C11: 1495 | D11: 1838 | E11: 2620 | F11: 2633 | G11: 2537 | H11: 2446 | I11: 6380 | J11: 6047 | K11: 4947
A12: + Notes Receivable, Net | B12: 0 | C12: 0 | D12: 0 | E12: 0 | F12: 0 | G12: 0 | H12: 0 | I12: 0 | J12: 0 | K12: 0
A13: + Inventories | B13: 0 | C13: 0 | D13: 0 | E13: 0 | F13: 0 | G13: 0 | H13: 0 | I13: 0 | J13: 0 | K13: 0
A14: + Raw Materials | B14: 0 | C14: 0 | D14: 0 | E14: 0 | F14: 0 | G14: 0 | H14: 0 | I14: 0 | J14: 0 | K14: 0
A15: + Work In Process | B15: 0 | C15: 0 | D15: 0 | E15: 0 | F15: 0 | G15: 0 | H15: 0 | I15: 0 | J15: 0 | K15: 0
A16: + Finished Goods | B16: 0 | C16: 0 | D16: 0 | E16: 0 | F16: 0 | G16: 0 | H16: 0 | I16: 0 | J16: 0 | K16: 0
A17: + Other Inventory | B17: 0 | C17: 0 | D17: 0 | E17: 0 | F17: 0 | G17: 0 | H17: 0 | I17: 0 | J17: 0 | K17: 0
A18: + Other ST Assets | B18: 727 | C18: 707 | D18: 844 | E18: 625 | F18: 1032 | G18: 1502 | H18: 913 | I18: 3888 | J18: 4391 | K18: 3819
A19: + Derivative & Hedging Assets | B19: 21 | C19: 31 | D19: 9 | E19: 13 | F19: 66 | G19: 38 | H19: 241 | I19: 80 | J19: 90 | K19: 73
A20: + Deferred Tax Assets | B20: 68 | C20: — | D20: — | E20: — | F20: — | G20: — | H20: — | I20: — | J20: — | K20: —
A21: + Misc ST Assets | B21: 638 | C21: 676 | D21: 835 | E21: 612 | F21: 966 | G21: 1464 | H21: 672 | I21: 3808 | J21: 4301 | K21: 3746
A22: Total Current Assets | B22: 2596 | C22: 2502 | D22: 9991 | E22: 4231 | F22: 5217 | G22: 6130 | H22: 7264 | I22: 13999 | J22: 14218 | K22: 14078
A23: + Property, Plant & Equip, Net | B23: 488 | C23: 482 | D23: 597 | E23: 800 | F23: 1564 | G23: 1781 | H23: 1871 | I23: 8490 | J23: 9031 | K23: 8460
A24: + Property, Plant & Equip | B24: 1561 | C24: 1614 | D24: 1901 | E24: 1993 | F24: 2712 | G24: 3144 | H24: 3200 | I24: 10545 | J24: 12116 | K24: 12495
A25: - Accumulated Depreciation | B25: 1073 | C25: 1132 | D25: 1304 | E25: 1193 | F25: 1148 | G25: 1363 | H25: 1329 | I25: 2055 | J25: 3085 | K25: 4035
A26: + LT Investments & Receivables | B26: 567 | C26: 557 | D26: 335 | E26: 935 | F26: 568 | G26: 507 | H26: 543 | I26: 1588 | J26: 1487 | K26: 1115
A27: + LT Investments | B27: 567 | C27: 557 | D27: 335 | E27: 935 | F27: 568 | G27: 507 | H27: 543 | I27: 1588 | J27: 1487 | K27: 1115
A28: + Other LT Assets | B28: 12213 | C28: 12131 | D28: 11632 | E28: 26584 | F28: 26386 | G28: 25669 | H28: 24749 | I28: 109924 | J28: 98021 | K28: 80907
A29: + Total Intangible Assets | B29: 11924 | C29: 11641 | D29: 11056 | E29: 25749 | F29: 24846 | G29: 24149 | H29: 23061 | I29: 106072 | J29: 94483 | K29: 77068
A30: + Goodwill | B30: 8164 | C30: 8040 | D30: 7073 | E30: 13006 | F30: 13050 | G30: 13070 | H30: 12912 | I30: 34438 | J30: 34969 | K30: 25667
A31: + Other Intangible Assets | B31: 3760 | C31: 3601 | D31: 3983 | E31: 12743 | F31: 11796 | G31: 11079 | H31: 10149 | I31: 71634 | J31: 59514 | K31: 51401
A32: + Deferred Tax Assets | B32: 86 | C32: — | D32: — | E32: — | F32: — | G32: — | H32: — | I32: — | J32: — | K32: —
A33: + Derivative & Hedging Assets | B33: 17 | C33: 35 | D33: 3 | E33: 42 | F33: 119 | G33: 57 | H33: 89 | I33: 106 | J33: 21 | K33: 21
A34: + Misc LT Assets | B34: 186 | C34: 455 | D34: 573 | E34: 793 | F34: 1421 | G34: 1463 | H34: 1599 | I34: 3746 | J34: 3517 | K34: 3818
A35: Total Noncurrent Assets | B35: 13268 | C35: 13170 | D35: 12564 | E35: 28319 | F35: 28518 | G35: 27957 | H35: 27163 | I35: 120002 | J35: 108539 | K35: 90482
A36: Total Assets | B36: 15864 | C36: 15672 | D36: 22555 | E36: 32550 | F36: 33735 | G36: 34087 | H36: 34427 | I36: 134001 | J36: 122757 | K36: 104560
A38: Liabilities & Shareholders' Equity
A39: + Payables & Accruals | B39: 1266 | C39: 1295 | D39: 1553 | E39: 1887 | F39: 2000 | G39: 2048 | H39: 2446 | I39: 12473 | J39: 11177 | K39: 11024
A40: + Accounts Payable | B40: 282 | C40: 241 | D40: 277 | E40: 325 | F40: 463 | G40: 397 | H40: 412 | I40: 1454 | J40: 1260 | K40: 1055
A41: + Accrued Taxes | B41: 30 | C41: 34 | D41: 45 | E41: — | F41: — | G41: — | H41: — | I41: — | J41: — | K41: —
A42: + Interest & Dividends Payable | B42: 61 | C42: 67 | D42: 148 | E42: — | F42: — | G42: — | H42: — | I42: — | J42: — | K42: —
A43: + Other Payables & Accruals | B43: 893 | C43: 953 | D43: 1083 | E43: 1562 | F43: 1537 | G43: 1651 | H43: 2034 | I43: 11019 | J43: 9917 | K43: 9969
...

Sheet WBD Cash Flow - Standardized
A2: Warner Bros Discovery Inc (WBD US) - Standardized
A4: In Millions of USD except Per Share | B4: FY 2016 | C4: FY 2017 | D4: FY 2018 | E4: FY 2019 | F4: FY 2020 | G4: FY 2021 | H4: FY 2022 | I4: FY 2023 | J4: FY 2024 | K4: Last 12M
A5: 12 Months Ending | B5: 42735 | C5: 43100 | D5: 43465 | E5: 43830 | F5: 44196 | G5: 44561 | H5: 44926 | I5: 45291 | J5: 45657 | K5: 45930
A6: Cash from Operating Activities
A7: + Net Income | B7: 1194 | C7: -337 | D7: 594 | E7: 2069 | F7: 1219 | G7: 1006 | H7: -7371 | I7: -3126 | J7: -11311 | K7: 485
A8: + Depreciation & Amortization | B8: 322 | C8: 330 | D8: 1398 | E8: 1347 | F8: 1359 | G8: 1582 | H8: 7193 | I8: 7985 | J8: 7037 | K8: 6012
A9: + Non-Cash Items | B9: -70 | C9: 1609 | D9: 742 | E9: -132 | F9: 187 | G9: -22 | H9: 2772 | I9: 3126 | J9: 9166 | K9: -2124
A10: + Stock-Based Compensation | B10: 69 | C10: 39 | D10: 80 | E10: 142 | F10: 110 | G10: 178 | H10: 412 | I10: 500 | J10: 557 | K10: 678
A11: + Deferred Income Taxes | B11: -27 | C11: -199 | D11: -131 | E11: -504 | F11: -186 | G11: -511 | H11: -2842 | I11: -2344 | J11: -1732 | K11: -653
A12: + Other Non-Cash Adj | B12: -112 | C12: 1769 | D12: 793 | E12: 230 | F12: 263 | G12: 311 | H12: 5202 | I12: 4970 | J12: 10341 | K12: -2149
A13: + Chg in Non-Cash Work Cap | B13: -66 | C13: 27 | D13: -158 | E13: 115 | F13: -26 | G13: 232 | H13: 1710 | I13: -508 | J13: 483 | K13: 857
A14: + (Inc) Dec in Accts Receiv | B14: -25 | C14: -258 | D14: -84 | E14: -7 | F14: 105 | G14: 47 | H14: 181 | I14: 312 | J14: 1012 | K14: 295
A15: + (Inc) Dec in Inventories | B15: 0 | C15: — | D15: — | E15: — | F15: — | G15: — | H15: — | I15: 0 | J15: 0 | K15: 0
A16: + Inc (Dec) in Accts Payable | B16: — | C16: — | D16: — | E16: — | F16: — | G16: — | H16: — | I16: 0 | J16: 0 | K16: 0
A17: + Inc (Dec) in Other | B17: -41 | C17: 285 | D17: -74 | E17: 122 | F17: -131 | G17: 185 | H17: 1529 | I17: -820 | J17: -529 | K17: 562
A18: + Net Cash From Disc Ops | B18: 0 | C18: 0 | D18: 0 | E18: 0 | F18: 0 | G18: 0 | H18: 0 | I18: 0 | J18: 0 | K18: 0
A19: Cash from Operating Activities | B19: 1380 | C19: 1629 | D19: 2576 | E19: 3399 | F19: 2739 | G19: 2798 | H19: 4304 | I19: 7477 | J19: 5375 | K19: 5230
A21: Cash from Investing Activities
A22: + Change in Fixed & Intang | B22: -88 | C22: -135 | D22: -40 | E22: -289 | F22: -402 | G22: -373 | H22: -987 | I22: -1316 | J22: -948 | K22: -1030
A23: + Disp in Fixed & Intang | B23: 0 | C23: 0 | D23: 107 | E23: 0 | F23: 0 | G23: 0 | H23: 0 | I23: 0 | J23: 0 | K23: 66
A24: + Disp of Fixed Prod Assets | B24: 0 | C24: 0 | D24: 107 | E24: 0 | F24: 0 | G24: 0 | H24: 0 | I24: 0 | J24: 0 | K24: 66
A25: + Disp of Intangible Assets | B25: 0 | C25: 0 | D25: 0 | E25: 0 | F25: 0 | G25: 0 | H25: 0 | I25: 0 | J25: 0 | K25: 0
A26: + Acq of Fixed & Intang | B26: -88 | C26: -135 | D26: -147 | E26: -289 | F26: -402 | G26: -373 | H26: -987 | I26: -1316 | J26: -948 | K26: -1096
A27: + Acq of Fixed Prod Assets | B27: -88 | C27: -135 | D27: -147 | E27: -289 | F27: -402 | G27: -373 | H27: -987 | I27: -1316 | J27: -948 | K27: -1096
A28: + Acq of Intangible Assets | B28: 0 | C28: 0 | D28: 0 | E28: 0 | F28: 0 | G28: 0 | H28: 0 | I28: 0 | J28: 0 | K28: 0
A29: + Net Change in LT Investment | B29: 0 | C29: 0 | D29: 0 | E29: 0 | F29: -250 | G29: 0 | H29: 0 | I29: 0 | J29: 0 | K29: 0
A30: + Dec in LT Investment | B30: 0 | C30: 0 | D30: 0 | E30: 0 | F30: 0 | G30: 0 | H30: 0 | I30: 0 | J30: 0 | K30: 0
A31: + Inc in LT Investment | B31: 0 | C31: 0 | D31: 0 | E31: 0 | F31: -250 | G31: 0 | H31: 0 | I31: 0 | J31: 0 | K31: 0
A32: + Net Cash From Acq & Div | B32: 19 | C32: -31 | D32: -8565 | E32: -73 | F32: -39 | G32: -2 | H32: 3612 | I32: -50 | J32: 0 | K32: 0
A33: + Cash from Divestitures | B33: 19 | C33: 29 | D33: 0 | E33: 0 | F33: 0 | G33: 0 | H33: 0 | I33: 0 | J33: 0 | K33: 0
... A38: Cash from Investing Activities | B38: -256 | C38: -633 | D38: -8593 | E38: -438 | F38: -703 | G38: -56 | H38: 3524 | I38: -1259 | J38: -349 | K38: -755
A40: Cash from Financing Activities
A41: + Dividends Paid | B41: 0 | C41: 0 | D41: 0 | E41: 0 | F41: 0 | G41: 0 | H41: 0 | I41: 0 | J41: 0 | K41: 0
A42: + Cash From (Repayment) Debt | B42: 243 | C42: 6632 | D42: -216 | E42: -1404 | F42: -214 | G42: -574 | H42: -7317 | I42: -5371 | J42: -3426 | K42: -3863
A43: + Cash From (Repay) ST Debt | B43: — | C43: — | D43: — | E43: — | F43: — | G43: — | H43: — | I43: — | J43: —
A44: + Cash From LT Debt | B44: — | C44: — | D44: — | E44: — | F44: — | G44: — | H44: — | I44: — | J44: —
A45: + Repayments of LT Debt | B45: — | C45: — | D45: — | E45: — | F45: — | G45: — | H45: — | I45: — | J45: —
A46: + Cash (Repurchase) of Equity | B46: -1374 | C46: -603 | D46: 0 | E46: -633 | F46: -969 | G46: 0 | H46: 0 | I46: 0 | J46: 0 | K46: 0
A47: + Increase in Capital Stock | B47: 0 | C47: 0 | D47: 0 | E47: 0 | F47: 0 | G47: 0 | H47: 0 | I47: 0 | J47: 0 | K47: 0
A48: + Decrease in Capital Stock | B48: -1374 | C48: -603 | D48: 0 | E48: -633 | F48: -969 | G48: 0 | H48: 0 | I48: 0 | J48: 0 | K48: 0
...

Sheet WBD DDIS
A1: Security Id | B1: FIGI | C1: Maturity Type | D1: Security Description | E1: Maturity | F1: Principal Due | G1: Amount Outstanding | H1: Interest | I1: Coupon | J1: Currency | K1: Normalized Payment Rank | L1: Yield to Maturity (Ask) | M1: Ask Price | N1: Bid Price | O1: Yield to Maturity (Bid) | P1: Yield to Maturity (Mid) | Q1: Mid Price
A2: QJ825220 Corp | B2: BBG00BGQW6K9 | C2: CALLABLE | D2: TWX 3 7/8 01/15/26 | E2: 1/15/2026 | F2: 20207000 | G2: 20207000 | H2: 391510.62 | I2: 3.875 | J2: USD | K2: Sr Unsecured | L2: 6.3423776 | M2: 99.759 | N2: 99.616 | O2: 7.8476889 | P2: 7.0945018 | Q2: 99.6875
A3: DD104551 Corp | B3: BBG00002SM78 | C3: PUTABLE | D3: TWX 6.85 01/15/26 | E3: 1/15/2026 | F3: 1581000 | G3: 1581000 | H3: 54149.25 | I3: 6.85 | J3: USD | K3: Sr Unsecured | L3: 5.1534285 | M3: 100.146 | N3: 100.017 | O3: 6.4886389 | P3: 5.8206151 | Q3: 100.0815
A4: JK392862 Corp | B4: BBG00CF29B44 | C4: CALLABLE | D4: WBD 4.9 03/11/26 | E4: 3/11/2026 | F4: 101864000 | G4: 101864000 | H4: 2495668 | I4: 4.9 | J4: USD | K4: Sr Unsecured | L4: 5.738557 | M4: 99.776 | N4: 99.634 | O4: 6.3097988 | P4: 6.023977 | Q4: 99.705
A5: LW043714 Corp | B5: BBG00CVR51H3 | C5: CALLABLE | D5: TWX 2.95 07/15/26 | E5: 7/15/2026 | F5: 16195000 | G5: 16195000 | H5: 477752.5 | I5: 2.95 | J5: USD | K5: Sr Unsecured | L5: 4.9041577 | M5: 98.866 | N5: 98.526 | O5: 5.49898 | P5: 5.2010976 | Q5: 98.696
A6: AL482791 Corp | B6: BBG00FFJXSB8 | C6: CALLABLE | D6: TWX 3.8 02/15/27 | E6: 2/15/2027 | F6: 33955000 | G6: 33955000 | H6: 1935435 | I6: 3.8 | J6: USD | K6: Sr Unsecured | L6: 5.7549569 | M6: 97.798 | N6: 97.572 | O6: 5.9595483 | P6: 5.8571677 | Q6: 97.685
A7: ZK031353 Corp | B7: BBG01G4GFLH2 | C7: CALLABLE | D7: WBD 3.755 03/15/27 | E7: 3/15/2027 | F7: 154696000 | G7: 154696000 | H7: 8713252.2 | I7: 3.755 | J7: USD | K7: Sr Unsecured | L7: 5.2436197 | M7: 98.2 | N7: 97.764 | O7: 5.6108614 | P7: 5.4269531 | Q7: 97.982
A8: BV124586 Corp | B8: BBG015XRXZP0 | C8: CALLABLE | D8: WBD 3.755 03/15/27 | E8: 3/15/2027 | F8: 72000 | G8: 72000 | H8: 4055.4 | I8: 3.755 | J8: USD | K8: Sr Unsecured | L8: 5.2436197 | M8: 98.2 | N8: 97.764 | O8: 5.6108614 | P8: 5.4269531 | Q8: 97.982
A9: YN708866 Corp | B9: BBG01VRP6H74 | C9: CALLABLE | D9: WBD 3.755 03/15/27 | E9: 3/15/2027 | F9: 1194766000 | G9: 1194766000 | H9: 67295195 | I9: 3.755 | J9: USD | K9: Sr Unsecured | L9: 4.4372458 | M9: 99.167 | N9: 98.972 | O9: 4.5989618 | P9: 4.5180478 | Q9: 99.0695
A10: YN704713 Corp | B10: BBG01VRNHS64 | C10: CALLABLE | D10: WBD 3.755 03/15/27 | E10: 3/15/2027 | F10: 505000 | G10: 505000 | H10: 28444.125 | I10: 3.755 | J10: USD | K10: Sr Unsecured | L10: 4.4372458 | M10: 99.167 | N10: 98.972 | O10: 4.5989618 | P10: 4.5180478 | Q10: 99.0695
A11: EK800869 Corp | B11: BBG0088LF1M4 | C11: CALLABLE | D11: WBD 1.9 03/19/27 | E11: 3/19/2027 | F11: 98099312 | G11: 84285000 | H11: 3727773.8 | I11: 1.9 | J11: EUR | K11: Sr Unsecured | L11: 3.4697508 | M11: =1.17*98.082 -> 114.75594 | N11: 97.078 | O11: 4.3150561 | P11: 3.890459 | Q11: 97.58
A12: CP502886 Corp | B12: BBG00005S8Q1 | C12: AT MATURITY | D12: TWX 6.95 01/15/28 | E12: 1/15/2028 | F12: 19412000 | G12: 19412000 | H12: 3372835 | I12: 6.95 | J12: USD | K12: Sr Unsecured | L12: 6.6871965 | M12: 100.497 | N12: 99.386 | O12: 7.2663237 | P12: 6.9757287 | Q12: 99.9415
A13: YN746464 Corp | B13: BBG01VS2MRF5 | C13: CALLABLE | D13: WBD 3.95 03/20/28 | E13: 3/20/2028 | F13: 1249026000 | G13: 1249026000 | H13: 1.2334132e+08 | I13: 3.95 | J13: USD | K13: Sr Unsecured | L13: 4.8749249 | M13: 98.025 | N13: 97.731 | O13: 5.0149307 | P13: 4.9448623 | Q13: 97.878
A14: AP073507 Corp | B14: BBG00HNJFY13 | C14: CALLABLE | D14: WBD 3.95 03/20/28 | E14: 3/20/2028 | F14: 140339000 | G14: 140339000 | H14: 13858476 | I14: 3.95 | J14: USD | K14: Sr Unsecured | L14: 6.4524636 | M14: 94.775 | N14: 94.29 | O14: 6.6936644 | P14: 6.5728711 | Q14: 94.5325
A15: YN715516 Corp | B15: BBG01VRRC944 | C15: CALLABLE | D15: WBD 4.054 03/15/29 | E15: 3/15/2029 | F15: 1357989000 | G15: 1357989000 | H15: 1.9268506e+08 | I15: 4.054 | J15: USD | K15: Sr Unsecured | L15: 5.1141816 | M15: 96.846 | N15: 96.56 | O15: 5.212509 | P15: 5.1633019 | Q15: 96.703
A16: ZK031439 Corp | B16: BBG01G4GFWX0 | C16: CALLABLE | D16: WBD 4.054 03/15/29 | E16: 3/15/2029 | F16: 134476000 | G16: 134476000 | H16: 19080800 | I16: 4.054 | J16: USD | K16: Sr Unsecured | L16: 6.18253 | M16: 93.792 | N16: 92.975 | O16: 6.4754027 | P16: 6.3285831 | Q16: 93.3835
A17: BV124611 Corp | B17: BBG015XRY1Y4 | C17: CALLABLE | D17: WBD 4.054 03/15/29 | E17: 3/15/2029 | F17: 905000 | G17: 905000 | H17: 128410.45 | I17: 4.054 | J17: USD | K17: Sr Unsecured | L17: 6.18253 | M17: 93.792 | N17: 92.975 | O17: 6.4754027 | P17: 6.3285831 | Q17: 93.3835
A18: YN714749 Corp | B18: BBG01VRQWQN5 | C18: CALLABLE | D18: WBD 4.054 03/15/29 | E18: 3/15/2029 | F18: 6630000 | G18: 6630000 | H18: 940730.7 | I18: 4.054 | J18: USD | K18: Sr Unsecured | L18: 5.1141816 | M18: 96.846 | N18: 96.56 | O18: 5.212509 | P18: 5.1633019 | Q18: 96.703
A19: EC070000 Corp | B19: BBG00000VQL3 | C19: AT MATURITY | D19: TWX 6 5/8 05/15/29 | E19: 5/15/2029 | F19: 24356000 | G19: 24356000 | H19: 5647547.5 | I19: 6.625 | J19: USD | K19: Sr Unsecured | L19: 6.5947019 | M19: 100.085 | N19: 99.232 | O19: 6.8780224 | P19: 6.7359931 | Q19: 99.6585
A20: YN746989 Corp | B20: BBG01VS2TLL4 | C20: CALLABLE | D20: WBD 4 1/8 05/15/29 | E20: 5/15/2029 | F20: 662268000 | G20: 662268000 | H20: 95614942 | I20: 4.125 | J20: USD | K20: Sr Unsecured | L20: 5.3226141 | M20: 96.289 | N20: 96.091 | O20: 5.3880974 | P20: 5.3553356 | Q20: 96.19
A21: ZS706214 Corp | B21: BBG00P5CG941 | C21: CALLABLE | D21: WBD 4 1/8 05/15/29 | E21: 5/15/2029 | F21: 87732000 | G21: 87732000 | H21: 12666308 | I21: 4.125 | J21: USD | K21: Sr Unsecured | L21: 6.3423544 | M21: 93.26 | N21: 92.885 | O21: 6.4713458 | P21: 6.4067726 | Q21: 93.0725
A22: YN745938 Corp | B22: BBG01VS2DCW9 | C22: CALLABLE | D22: WBD 4.302 01/17/30 | E22: 1/17/2030 | F22: 2.8488548e+08 | G22: =1.17*244768000 -> 286378560 | H22: 61278866 | I22: 4.302 | J22: EUR | K22: Sr Unsecured | L22: 4.5933472 | M22: =1.17*98.925 -> 115.74225 | N22: 97.904 | O22: 4.8760004 | P22: 4.7341985 | Q22: 98.4145
A23: YX013967 Corp | B23: BBG01MSYW232 | C23: CALLABLE | D23: WBD 4.302 01/17/30 | E23: 1/17/2030 | F23: 65538045 | G23: =1.17*56309000 -> 65881530 | H23: 14097234 | I23: 4.302 | J23: EUR | K23: Sr Unsecured | L23: 5.2553744 | M23: =1.17*96.555 -> 112.96935 | N23: 94.561 | O23: 5.8289152 | P23: 5.5402035 | Q23: 95.558
